2025-02-26 19:26:36,744 - INFO - Starting receiving_data.py
2025-02-26 19:26:36,744 - INFO - Server listening on 192.168.1.3:9000
2025-02-26 19:26:36,744 - INFO - Waiting for connection...
2025-02-26 19:26:47,786 - INFO - Got a connection from ('192.168.1.3', 47158)
2025-02-26 19:26:49,890 - INFO - Connection closed. Received 68 bytes in 2 chunks
2025-02-26 19:26:49,890 - INFO - Data decoded successfully, length: 68
2025-02-26 19:26:49,890 - INFO - Attempting to parse JSON data
2025-02-26 19:26:49,891 - ERROR - Failed to parse JSON: Expected object or value
Traceback (most recent call last):
  File "/home/mohamed/Desktop/workstation/FL-CML-Pipeline/data/receiving_data.py", line 80, in start_server
    df = pd.read_json(data_str, orient='records')
  File "/home/mohamed/.pyenv/versions/3.10.4/lib/python3.10/site-packages/pandas/io/json/_json.py", line 815, in read_json
    return json_reader.read()
  File "/home/mohamed/.pyenv/versions/3.10.4/lib/python3.10/site-packages/pandas/io/json/_json.py", line 1025, in read
    obj = self._get_object_parser(self.data)
  File "/home/mohamed/.pyenv/versions/3.10.4/lib/python3.10/site-packages/pandas/io/json/_json.py", line 1051, in _get_object_parser
    obj = FrameParser(json, **kwargs).parse()
  File "/home/mohamed/.pyenv/versions/3.10.4/lib/python3.10/site-packages/pandas/io/json/_json.py", line 1187, in parse
    self._parse()
  File "/home/mohamed/.pyenv/versions/3.10.4/lib/python3.10/site-packages/pandas/io/json/_json.py", line 1430, in _parse
    ujson_loads(json, precise_float=self.precise_float), dtype=None
ValueError: Expected object or value
2025-02-26 19:26:49,891 - ERROR - Error handling connection: [Errno 2] No such file or directory: 'data/invalid_json_20250226_192647.txt'
Traceback (most recent call last):
  File "/home/mohamed/Desktop/workstation/FL-CML-Pipeline/data/receiving_data.py", line 80, in start_server
    df = pd.read_json(data_str, orient='records')
  File "/home/mohamed/.pyenv/versions/3.10.4/lib/python3.10/site-packages/pandas/io/json/_json.py", line 815, in read_json
    return json_reader.read()
  File "/home/mohamed/.pyenv/versions/3.10.4/lib/python3.10/site-packages/pandas/io/json/_json.py", line 1025, in read
    obj = self._get_object_parser(self.data)
  File "/home/mohamed/.pyenv/versions/3.10.4/lib/python3.10/site-packages/pandas/io/json/_json.py", line 1051, in _get_object_parser
    obj = FrameParser(json, **kwargs).parse()
  File "/home/mohamed/.pyenv/versions/3.10.4/lib/python3.10/site-packages/pandas/io/json/_json.py", line 1187, in parse
    self._parse()
  File "/home/mohamed/.pyenv/versions/3.10.4/lib/python3.10/site-packages/pandas/io/json/_json.py", line 1430, in _parse
    ujson_loads(json, precise_float=self.precise_float), dtype=None
ValueError: Expected object or value

During handling of the above exception, another exception occurred:

Traceback (most recent call last):
  File "/home/mohamed/Desktop/workstation/FL-CML-Pipeline/data/receiving_data.py", line 96, in start_server
    with open(f'data/invalid_json_{timestamp}.txt', 'w') as f:
FileNotFoundError: [Errno 2] No such file or directory: 'data/invalid_json_20250226_192647.txt'
2025-02-26 19:26:49,892 - INFO - Waiting for connection...
2025-02-26 19:27:19,923 - INFO - Got a connection from ('192.168.1.3', 54164)
2025-02-26 19:27:22,027 - INFO - Connection closed. Received 68 bytes in 2 chunks
2025-02-26 19:27:22,027 - INFO - Data decoded successfully, length: 68
2025-02-26 19:27:22,027 - INFO - Attempting to parse JSON data
2025-02-26 19:27:22,028 - ERROR - Failed to parse JSON: Expected object or value
Traceback (most recent call last):
  File "/home/mohamed/Desktop/workstation/FL-CML-Pipeline/data/receiving_data.py", line 80, in start_server
    df = pd.read_json(data_str, orient='records')
  File "/home/mohamed/.pyenv/versions/3.10.4/lib/python3.10/site-packages/pandas/io/json/_json.py", line 815, in read_json
    return json_reader.read()
  File "/home/mohamed/.pyenv/versions/3.10.4/lib/python3.10/site-packages/pandas/io/json/_json.py", line 1025, in read
    obj = self._get_object_parser(self.data)
  File "/home/mohamed/.pyenv/versions/3.10.4/lib/python3.10/site-packages/pandas/io/json/_json.py", line 1051, in _get_object_parser
    obj = FrameParser(json, **kwargs).parse()
  File "/home/mohamed/.pyenv/versions/3.10.4/lib/python3.10/site-packages/pandas/io/json/_json.py", line 1187, in parse
    self._parse()
  File "/home/mohamed/.pyenv/versions/3.10.4/lib/python3.10/site-packages/pandas/io/json/_json.py", line 1430, in _parse
    ujson_loads(json, precise_float=self.precise_float), dtype=None
ValueError: Expected object or value
2025-02-26 19:27:22,028 - ERROR - Error handling connection: [Errno 2] No such file or directory: 'data/invalid_json_20250226_192719.txt'
Traceback (most recent call last):
  File "/home/mohamed/Desktop/workstation/FL-CML-Pipeline/data/receiving_data.py", line 80, in start_server
    df = pd.read_json(data_str, orient='records')
  File "/home/mohamed/.pyenv/versions/3.10.4/lib/python3.10/site-packages/pandas/io/json/_json.py", line 815, in read_json
    return json_reader.read()
  File "/home/mohamed/.pyenv/versions/3.10.4/lib/python3.10/site-packages/pandas/io/json/_json.py", line 1025, in read
    obj = self._get_object_parser(self.data)
  File "/home/mohamed/.pyenv/versions/3.10.4/lib/python3.10/site-packages/pandas/io/json/_json.py", line 1051, in _get_object_parser
    obj = FrameParser(json, **kwargs).parse()
  File "/home/mohamed/.pyenv/versions/3.10.4/lib/python3.10/site-packages/pandas/io/json/_json.py", line 1187, in parse
    self._parse()
  File "/home/mohamed/.pyenv/versions/3.10.4/lib/python3.10/site-packages/pandas/io/json/_json.py", line 1430, in _parse
    ujson_loads(json, precise_float=self.precise_float), dtype=None
ValueError: Expected object or value

During handling of the above exception, another exception occurred:

Traceback (most recent call last):
  File "/home/mohamed/Desktop/workstation/FL-CML-Pipeline/data/receiving_data.py", line 96, in start_server
    with open(f'data/invalid_json_{timestamp}.txt', 'w') as f:
FileNotFoundError: [Errno 2] No such file or directory: 'data/invalid_json_20250226_192719.txt'
2025-02-26 19:27:22,029 - INFO - Waiting for connection...
2025-02-26 19:27:40,941 - INFO - Server stopped by user
2025-02-26 19:27:40,941 - INFO - Server socket closed
2025-02-26 19:29:00,262 - INFO - Starting receiving_data.py
2025-02-26 19:29:00,262 - INFO - Server listening on 192.168.1.3:9000
2025-02-26 19:29:00,262 - INFO - Waiting for connection...
2025-02-26 19:29:38,133 - INFO - Server stopped by user
2025-02-26 19:29:38,134 - INFO - Server socket closed
2025-02-26 19:31:29,053 - INFO - Starting receiving_data.py
2025-02-26 19:31:29,053 - INFO - Server listening on 192.168.1.3:9000
2025-02-26 19:31:29,053 - INFO - Waiting for connection...
2025-02-26 19:32:44,329 - INFO - Server stopped by user
2025-02-26 19:32:44,329 - INFO - Server socket closed
